Workbook
Name _Fill: #REF!
Name _Fill: #REF!
Name _Key2: #REF!
Name _Key2: #REF!
Name _Sort: #REF!
Name _Table2_In2: #REF!
Name _Table2_Out: #REF!
Name cap: #REF!
Name d: #REF!
Name dfasfasf: #REF!
Name increase: #REF!
Name increase1: #REF!
Name MasterCheck: #REF!
Name newsf: #REF!
Name rate: #REF!
Name RentRollProperty: #REF!
Name salesprice: #REF!
Name salesprice: #REF!
Name SnapshotAnnexRow: #REF!
Name SnapshotAutofilter1: #REF!
Name SnapshotProperty: #REF!
Name SnapshotSqFtRentedPercent: #REF!
Name SnapshotUnitRentedPercent: #REF!
Name transpose07occ: #REF!
Name transpose08occ: #REF!
Name transpose09occ: #REF!
Name UnitMixProperty: #REF!

Sheet How to

Sheet Summary
H1: Year | I1: Year | J1: Year | K1: Year | L1: Year
G2: In-Place | H2: 1 | I2: =H2+1 -> 2 | J2: =I2+1 -> 3 | K2: =J2+1 -> 4 | L2: =K2+1 -> 5
B3: Assumptions | E3: Average Rates
B4: Starting Rate | C4: =Projection!I30 -> 17.789291 | F4: Occupancy | G4: =$C$24/$C$23 -> 0 | H4: =AVERAGEIF(Monthly!$2:$2,Summary!H$2,Monthly!$6:$6) -> 0.18741743 | I4: =AVERAGEIF(Monthly!$2:$2,Summary!I$2,Monthly!$6:$6) -> 0.52877606 | J4: =AVERAGEIF(Monthly!$2:$2,Summary!J$2,Monthly!$6:$6) -> 0.81630358 | K4: =AVERAGEIF(Monthly!$2:$2,Summary!K$2,Monthly!$6:$6) -> 0.92 | L4: =AVERAGEIF(Monthly!$2:$2,Summary!L$2,Monthly!$6:$6) -> 0.91760417
F5: Rental Rate | G5: =$C$4 -> 17.789291 | H5: =AVERAGEIF(Monthly!$2:$2,Summary!H$2,Monthly!$10:$10) -> 18.918678 | I5: =AVERAGEIF(Monthly!$2:$2,Summary!I$2,Monthly!$10:$10) -> 19.607006 | J5: =AVERAGEIF(Monthly!$2:$2,Summary!J$2,Monthly!$10:$10) -> 20.320378 | K5: =AVERAGEIF(Monthly!$2:$2,Summary!K$2,Monthly!$10:$10) -> 21.059704 | L5: =AVERAGEIF(Monthly!$2:$2,Summary!L$2,Monthly!$10:$10) -> 21.812382
B6: Rate Growth | F6: Avg. Rental Rate | H6: =AVERAGEIF(Monthly!$2:$2,Summary!H$2,Monthly!$23:$23) -> 19.265521 | I6: =AVERAGEIF(Monthly!$2:$2,Summary!I$2,Monthly!$23:$23) -> 19.966468 | J6: =AVERAGEIF(Monthly!$2:$2,Summary!J$2,Monthly!$23:$23) -> 20.413654 | K6: =AVERAGEIF(Monthly!$2:$2,Summary!K$2,Monthly!$23:$23) -> 20.553838 | L6: =AVERAGEIF(Monthly!$2:$2,Summary!L$2,Monthly!$23:$23) -> 21.313117
B7: 1 | C7: =Inputs!I19 -> 0.04 | F7: Implied Full-Price Rate | H7: =AVERAGEIF(Monthly!$2:$2,Summary!H$2,Monthly!$12:$12) -> 0 | I7: =AVERAGEIF(Monthly!$2:$2,Summary!I$2,Monthly!$12:$12) -> 0 | J7: =AVERAGEIF(Monthly!$2:$2,Summary!J$2,Monthly!$12:$12) -> 0 | K7: =AVERAGEIF(Monthly!$2:$2,Summary!K$2,Monthly!$12:$12) -> 0 | L7: =AVERAGEIF(Monthly!$2:$2,Summary!L$2,Monthly!$12:$12) -> 0
B8: 2 | C8: =Inputs!I20 -> 0.04 | F8: Implied Internet Rate | H8: =AVERAGEIF(Monthly!$2:$2,Summary!H$2,Monthly!$13:$13) -> 0 | I8: =AVERAGEIF(Monthly!$2:$2,Summary!I$2,Monthly!$13:$13) -> 0 | J8: =AVERAGEIF(Monthly!$2:$2,Summary!J$2,Monthly!$13:$13) -> 0 | K8: =AVERAGEIF(Monthly!$2:$2,Summary!K$2,Monthly!$13:$13) -> 0 | L8: =AVERAGEIF(Monthly!$2:$2,Summary!L$2,Monthly!$13:$13) -> 0
B9: 3 | C9: =Inputs!I21 -> 0.04
B10: 4 | C10: =Inputs!I22 -> 0.04 | F10: In-Place Rate | G10: =IFERROR($C$25/$C$24*12,0) -> 0 | H10: =H24/(H4*$C$23) -> 19.859233 | I10: =I24/(I4*$C$23) -> 20.810242 | J10: =J24/(J4*$C$23) -> 21.794342 | K10: =K24/(K4*$C$23) -> 22.648495 | L10: =L24/(L4*$C$23) -> 31.686167
B11: 5 | C11: =Inputs!I23 -> 0.04 | F11: Achieved Rate | H11: =H27/(H4*$C$23) -> 15.346934 | I11: =I27/(I4*$C$23) -> 17.945767 | J11: =J27/(J4*$C$23) -> 19.927324 | K11: =K27/(K4*$C$23) -> 21.735555 | L11: =L27/(L4*$C$23) -> 30.474012
B13: Property Age | C13: =Inputs!C10 -> 1 | E13: Ending Rates
F14: Occupancy | G14: =$C$24/$C$23 -> 0 | H14: =SUMIFS(Monthly!$6:$6,Monthly!$3:$3,12*Summary!H$2,Monthly!$2:$2,Summary!H$2) -> 0.33 | I14: =SUMIFS(Monthly!$6:$6,Monthly!$3:$3,12*Summary!I$2,Monthly!$2:$2,Summary!I$2) -> 0.68 | J14: =SUMIFS(Monthly!$6:$6,Monthly!$3:$3,12*Summary!J$2,Monthly!$2:$2,Summary!J$2) -> 0.92 | K14: =SUMIFS(Monthly!$6:$6,Monthly!$3:$3,12*Summary!K$2,Monthly!$2:$2,Summary!K$2) -> 0.90766667 | L14: =SUMIFS(Monthly!$6:$6,Monthly!$3:$3,12*Summary!L$2,Monthly!$2:$2,Summary!L$2) -> 0.90766667
B15: Writeoff % | C15: =Inputs!J37 -> -0.01 | F15: Net Effective Rate | G15: =Monthly!C10 -> 17.789291 | H15: =SUMIFS(Monthly!$10:$10,Monthly!$3:$3,12*Summary!H$2,Monthly!$2:$2,Summary!H$2) -> 18.436528 | I15: =SUMIFS(Monthly!$10:$10,Monthly!$3:$3,12*Summary!I$2,Monthly!$2:$2,Summary!I$2) -> 19.107314 | J15: =SUMIFS(Monthly!$10:$10,Monthly!$3:$3,12*Summary!J$2,Monthly!$2:$2,Summary!J$2) -> 19.802505 | K15: =SUMIFS(Monthly!$10:$10,Monthly!$3:$3,12*Summary!K$2,Monthly!$2:$2,Summary!K$2) -> 20.522989 | L15: =SUMIFS(Monthly!$10:$10,Monthly!$3:$3,12*Summary!L$2,Monthly!$2:$2,Summary!L$2) -> 21.269687
F16: Implied Avg. Rental Rate | H16: =SUMIFS(Monthly!$23:$23,Monthly!$3:$3,12*Summary!H$2,Monthly!$2:$2,Summary!H$2) -> 18.774531 | I16: =SUMIFS(Monthly!$23:$23,Monthly!$3:$3,12*Summary!I$2,Monthly!$2:$2,Summary!I$2) -> 19.457614 | J16: =SUMIFS(Monthly!$23:$23,Monthly!$3:$3,12*Summary!J$2,Monthly!$2:$2,Summary!J$2) -> 19.333655 | K16: =SUMIFS(Monthly!$23:$23,Monthly!$3:$3,12*Summary!K$2,Monthly!$2:$2,Summary!K$2) -> 20.148214 | L16: =SUMIFS(Monthly!$23:$23,Monthly!$3:$3,12*Summary!L$2,Monthly!$2:$2,Summary!L$2) -> 20.881276
B17: Cust. Choice | C17: FALSE | F17: Implied Full-Price Rate | G17: =Monthly!C12 -> 0 | H17: =SUMIFS(Monthly!$12:$12,Monthly!$3:$3,12*Summary!H$2,Monthly!$2:$2,Summary!H$2) -> 0 | I17: =SUMIFS(Monthly!$12:$12,Monthly!$3:$3,12*Summary!I$2,Monthly!$2:$2,Summary!I$2) -> 0 | J17: =SUMIFS(Monthly!$12:$12,Monthly!$3:$3,12*Summary!J$2,Monthly!$2:$2,Summary!J$2) -> 0 | K17: =SUMIFS(Monthly!$12:$12,Monthly!$3:$3,12*Summary!K$2,Monthly!$2:$2,Summary!K$2) -> 0 | L17: =SUMIFS(Monthly!$12:$12,Monthly!$3:$3,12*Summary!L$2,Monthly!$2:$2,Summary!L$2) -> 0
B18: Cust Choice % | C18: 0.25 | F18: Implied Internet Rate | G18: =Monthly!C13 -> 0 | H18: =SUMIFS(Monthly!$13:$13,Monthly!$3:$3,12*Summary!H$2,Monthly!$2:$2,Summary!H$2) -> 0 | I18: =SUMIFS(Monthly!$13:$13,Monthly!$3:$3,12*Summary!I$2,Monthly!$2:$2,Summary!I$2) -> 0 | J18: =SUMIFS(Monthly!$13:$13,Monthly!$3:$3,12*Summary!J$2,Monthly!$2:$2,Summary!J$2) -> 0 | K18: =SUMIFS(Monthly!$13:$13,Monthly!$3:$3,12*Summary!K$2,Monthly!$2:$2,Summary!K$2) -> 0 | L18: =SUMIFS(Monthly!$13:$13,Monthly!$3:$3,12*Summary!L$2,Monthly!$2:$2,Summary!L$2) -> 0
B19: Non-FMF Disc | C19: -0.005
B20: Churn Adj. | C20: 0 | F20: In-Place Rate | G20: =IFERROR($C$25/$C$24*12,0) -> 0 | H20: =SUMIFS(Monthly!$40:$40,Monthly!$3:$3,12*Summary!H$2,Monthly!$2:$2,Summary!H$2) -> 20.160365 | I20: =SUMIFS(Monthly!$40:$40,Monthly!$3:$3,12*Summary!I$2,Monthly!$2:$2,Summary!I$2) -> 21.209467 | J20: =SUMIFS(Monthly!$40:$40,Monthly!$3:$3,12*Summary!J$2,Monthly!$2:$2,Summary!J$2) -> 22.05744 | K20: =SUMIFS(Monthly!$40:$40,Monthly!$3:$3,12*Summary!K$2,Monthly!$2:$2,Summary!K$2) -> 23.088462 | L20: =SUMIFS(Monthly!$40:$40,Monthly!$3:$3,12*Summary!L$2,Monthly!$2:$2,Summary!L$2) -> 24.114293
F21: Achieved Rate | H21: =SUMIFS(Monthly!$41:$41,Monthly!$3:$3,12*Summary!H$2,Monthly!$2:$2,Summary!H$2) -> 17.46595 | I21: =SUMIFS(Monthly!$41:$41,Monthly!$3:$3,12*Summary!I$2,Monthly!$2:$2,Summary!I$2) -> 18.996297 | J21: =SUMIFS(Monthly!$41:$41,Monthly!$3:$3,12*Summary!J$2,Monthly!$2:$2,Summary!J$2) -> 21.002753 | K21: =SUMIFS(Monthly!$41:$41,Monthly!$3:$3,12*Summary!K$2,Monthly!$2:$2,Summary!K$2) -> 22.181987 | L21: =SUMIFS(Monthly!$41:$41,Monthly!$3:$3,12*Summary!L$2,Monthly!$2:$2,Summary!L$2) -> 23.213143
B22: In-Place Metrics
B23: Total SF | C23: =Inputs!C13-Inputs!C23 -> 105807 | E23: Net Rental Income Buildup
B24: Occ SF | C24: =Inputs!C18 -> 0 | F24: Rental Income | H24: =SUMIF(Monthly!$2:$2,Summary!H$2,Monthly!34:34) -> 393810.09 | I24: =SUMIF(Monthly!$2:$2,Summary!I$2,Monthly!34:34) -> 1164295.8 | J24: =SUMIF(Monthly!$2:$2,Summary!J$2,Monthly!34:34) -> 1882391.1 | K24: =SUMIF(Monthly!$2:$2,Summary!K$2,Monthly!34:34) -> 2204659.7 | L24: =SUMIF(Monthly!$2:$2,Summary!L$2,Monthly!34:34) -> 3076376.5
B25: Proj Rent | C25: =Inputs!C20 -> 0 | F25: Discounts | H25: =SUMIF(Monthly!$2:$2,Summary!H$2,Monthly!35:35) -> -85541.134 | I25: =SUMIF(Monthly!$2:$2,Summary!I$2,Monthly!35:35) -> -148619.28 | J25: =SUMIF(Monthly!$2:$2,Summary!J$2,Monthly!35:35) -> -142431.67 | K25: =SUMIF(Monthly!$2:$2,Summary!K$2,Monthly!35:35) -> -66821.14 | L25: =SUMIF(Monthly!$2:$2,Summary!L$2,Monthly!35:35) -> -86923.078
F26: Write-Offs | H26: =SUMIF(Monthly!$2:$2,Summary!H$2,Monthly!36:36) -> -3938.1009 | I26: =SUMIF(Monthly!$2:$2,Summary!I$2,Monthly!36:36) -> -11642.958 | J26: =SUMIF(Monthly!$2:$2,Summary!J$2,Monthly!36:36) -> -18823.911 | K26: =SUMIF(Monthly!$2:$2,Summary!K$2,Monthly!36:36) -> -22046.597 | L26: =SUMIF(Monthly!$2:$2,Summary!L$2,Monthly!36:36) -> -30763.765
F27: Net Rental Income | H27: =SUMIF(Monthly!$2:$2,Summary!H$2,Monthly!37:37) -> 304330.86 | I27: =SUMIF(Monthly!$2:$2,Summary!I$2,Monthly!37:37) -> 1004033.5 | J27: =SUMIF(Monthly!$2:$2,Summary!J$2,Monthly!37:37) -> 1721135.5 | K27: =SUMIF(Monthly!$2:$2,Summary!K$2,Monthly!37:37) -> 2115792 | L27: =SUMIF(Monthly!$2:$2,Summary!L$2,Monthly!37:37) -> 2958689.6
F29: Ending In-Place Rate Growth | H29: =IFERROR(H20/G20-1,0) -> 0 | I29: =IFERROR(I20/H20-1,0) -> 0.052037838 | J29: =IFERROR(J20/I20-1,0) -> 0.039980844 | K29: =IFERROR(K20/J20-1,0) -> 0.04674261 | L29: =IFERROR(L20/K20-1,0) -> 0.044430467
F30: Full Year In-Place Rate Growth | H30: =IFERROR(H10/G10-1,0) -> 0 | I30: =IFERROR(I10/H10-1,0) -> 0.047887498 | J30: =IFERROR(J10/I10-1,0) -> 0.047289218 | K30: =IFERROR(K10/J10-1,0) -> 0.039191484 | L30: =IFERROR(L10/K10-1,0) -> 0.39904075
F31: Ann'l Achieved RPSF Growth | H31: =IFERROR(H11/G11-1,0) -> 0 | I31: =IFERROR(I11/H11-1,0) -> 0.16933893 | J31: =IFERROR(J11/I11-1,0) -> 0.11041915 | K31: =IFERROR(K11/J11-1,0) -> 0.090741335 | L31: =IFERROR(L11/K11-1,0) -> 0.40203512
F32: Disc % of Rental Income | H32: =H25/H24 -> -0.21721418 | I32: =I25/I24 -> -0.12764736 | J32: =J25/J24 -> -0.075665289 | K32: =K25/K24 -> -0.030309049 | L32: =L25/L24 -> -0.02825502

Sheet Inputs
B2: Basic Info | E2: Rental Income Assumptions | L2: Expense Assumptions | T2: Expense Calcluations for Model | X2: Market | Y2: GM Pay | Z2: SM Pay
B3: Address | C3: 250 Dolson Avenue | E3: Occupancy Inputs | L3: Payroll Expense | O3: Comp Data | P3: Override | Q3: Model | R3: Year 1 Total | U3: Hours | V3: Avg Rate | X3: Major Metro | Y3: 30.05 | Z3: 25.38
B4: City | C4: Middletown | E4: Current Occupancy | G4: 0 | I4: =(Inputs!C18-Inputs!C24)/(Inputs!C13-Inputs!C23) -> 0 | M4: # of Full-Time Employees | O4: =ROUNDDOWN($U$8/40,0) -> 1 | P4: 0 | Q4: =IF(P4=0,O4,P4) -> 1 | T4: Total Store Hours | U4: =IF(Inputs!$C$14<300,64,64+(INT(Inputs!$C$14/100-2)*8)) -> 96 | X4: National | Y4: 24.55 | Z4: 20.43
B5: State | C5: New York | H5: Rented SF | I5: Ending Occ % | J5: Avg Occ | L5: 6112 | M5: Medical Expense | N5: per FTE | P5: 822 | Q5: =IF(P5=0,O5,P5) -> 822 | R5: =Projection!$BW$85 -> 9864 | T5: Gen. Mgr | U5: 40 | V5: =Y9 -> 28.846154 | X5: Secondary | Y5: 19.82 | Z5: 16
B6: Zip | C6: 10940 | F6: =IF(G6<$I$12,"Occ @ End of Year:","Average Occ") -> Occ @ End of Year: | G6: 1 | H6: =Projection!U25 -> 34916.31 | I6: 0.33 | J6: =HLOOKUP($E19,Projection!$BW$7:$CC$24,18,FALSE) -> 0.18741743 | L6: 6130 | M6: Payroll Taxes | N6: % of Sal. | O6: =IFERROR(SUMIF('Expense Comp Data'!$B:$B,Inputs!$L6,'Expense Comp Data'!$I:$I)/SUMIF('Expense Comp Data'!$B:$B,6100,'Expense Comp Data'!$I:$I),"No Comps") -> No Comps | P6: 0.01 | Q6: =IF(P6=0,O6,P6) -> 0.01 | R6: =Projection!BW87 -> 601.33846 | T6: Manager | U6: 0 | V6: =Z9 -> 21.634615
B7: New Development? | C7: TRUE | F7: =IF(G7<$I$12,"Occ @ End of Year:","Average Occ") -> Occ @ End of Year: | G7: 2 | H7: =Projection!AG25 -> 71948.76 | I7: 0.68 | J7: =HLOOKUP($E20,Projection!$BW$7:$CC$24,18,FALSE) -> 0.52877606 | L7: 6283 | M7: Workers Comp. | N7: % of Sal. | O7: =IFERROR(SUMIF('Expense Comp Data'!$B:$B,Inputs!$L7,'Expense Comp Data'!$I:$I)/SUMIF('Expense Comp Data'!$B:$B,6100,'Expense Comp Data'!$I:$I),"No Comps") -> No Comps | P7: 0.01 | Q7: =IF(P7=0,O7,P7) -> 0.01 | R7: =Projection!BW89 -> 595.38462 | T7: Maint. | U7: 0 | X7: Market | Y7: GM Pay | Z7: SM Pay | AA7: Maintenance Pay
B8: Projection Start Date (EOM) | C8: 46053 | F8: =IF(G8<$I$12,"Occ @ End of Year:","Average Occ") -> Occ @ End of Year: | G8: 3 | H8: =Projection!AS25 -> 97342.44 | I8: 0.92 | J8: =HLOOKUP($E21,Projection!$BW$7:$CC$24,18,FALSE) -> 0.81630358 | R8: =Projection!BW90 -> 71789.954 | T8: Total | U8: =SUM(U5:U7) -> 40 | V8: =SUMPRODUCT($V$5:$V$7,$U$5:$U$7)/$U$8 -> 28.846154 | X8: Annual Salary | Y8: 60000 | Z8: 45000 | AA8: 50000
B9: 1 Year Budget/Upload Start | C9: =C8 -> 46053 | F9: =IF(G9<$I$12,"Occ @ End of Year:","Average Occ") -> Average Occ | G9: 4 | H9: =Projection!BE25 -> 96037.487 | I9: 0.92 | J9: =HLOOKUP($E22,Projection!$BW$7:$CC$24,18,FALSE) -> 0.92 | L9: Utility Expense | O9: Comp Data | P9: Override | Q9: Model | R9: Year 1 | X9: Hourly Rate | Y9: =Y8/2080 -> 28.846154 | Z9: =Z8/2080 -> 21.634615 | AA9: =AA8/2080 -> 24.038462
B10: Property Age (Years) | C10: 1 | F10: =IF(G10<$I$12,"Occ @ End of Year:","Average Occ") -> Average Occ | G10: 5 | H10: =Projection!BU25 -> 96883.943 | I10: 0.92 | J10: =HLOOKUP($E23,Projection!$BW$7:$CC$24,18,FALSE) -> 0.92 | L10: 6150 | M10: Rubbish Removal | N10: psf | O10: =IFERROR(SUMIF('Expense Comp Data'!$B:$B,Inputs!$L10,'Expense Comp Data'!$I:$I)/SUMIF('Expense Comp Data'!$B:$B,"SqFoot_Total",'Expense Comp Data'!$I:$I),"No Comps") -> No Comps | P10: 0.11 | Q10: =IF(P10=0,O10,P10) -> 0.11 | R10: =Projection!BW93 -> 11638.77 | T10: Year 1 Output | U10: Payroll | V10: =Projection!BW84 -> 59538.462
L11: 6158 | M11: Exterminating | N11: psf | O11: =IFERROR(SUMIF('Expense Comp Data'!$B:$B,Inputs!$L11,'Expense Comp Data'!$I:$I)/SUMIF('Expense Comp Data'!$B:$B,"SqFoot_Total",'Expense Comp Data'!$I:$I),"No Comps") -> No Comps | P11: 0.05 | Q11: =IF(P11=0,O11,P11) -> 0.05 | R11: =Projection!BW94 -> 5290.35
B12: Current Property Info | E12: 1st Fully Stable Year | I12: 4 | L12: 6184 | M12: Electric | N12: psf | O12: =IFERROR(SUMIF('Expense Comp Data'!$B:$B,Inputs!$L12,'Expense Comp Data'!$I:$I)/SUMIF('Expense Comp Data'!$B:$B,"SqFoot_Total",'Expense Comp Data'!$I:$I),"No Comps") -> No Comps | P12: 0.28 | Q12: =IF(P12=0,O12,P12) -> 0.28 | R12: =Projection!BW95 -> 29625.96 | T12: Historical Utility Expense Calculator
B13: Total Square Feet | C13: 105807 | E13: Stable Average Occupancy | I13: 0.92 | L13: 6185 | M13: Telephone | N13: psf | O13: =IFERROR(SUMIF('Expense Comp Data'!$B:$B,Inputs!$L13,'Expense Comp Data'!$I:$I)/SUMIF('Expense Comp Data'!$B:$B,"SqFoot_Total",'Expense Comp Data'!$I:$I),"No Comps") -> No Comps | P13: 0.05 | Q13: =IF(P13=0,O13,P13) -> 0.05 | R13: =Projection!BW96 -> 5290.35 | T13: Ann'l Expense | U13: Growth | V13: PSF
B14: Total Units | C14: 684 | L14: 6186 | M14: Water/Sewer | N14: psf | O14: =IFERROR(SUMIF('Expense Comp Data'!$B:$B,Inputs!$L14,'Expense Comp Data'!$I:$I)/SUMIF('Expense Comp Data'!$B:$B,"SqFoot_Total",'Expense Comp Data'!$I:$I),"No Comps") -> No Comps | P14: 0.12 | Q14: =IF(P14=0,O14,P14) -> 0.12 | R14: =Projection!BW97 -> 12696.84 | T14: 0 | U14: 0.025 | V14: =($T14*(1+U14))/Projection!$F$3 -> 0
A15: Owned | B15: Climated Controlled SF | C15: =C13 -> 105807 | E15: Rate Inputs | H15: IP Rate | I15: Rate Input | J15: Output | L15: 6187 | M15: Gas & Utilities | N15: psf | O15: =IFERROR(SUMIF('Expense Comp Data'!$B:$B,Inputs!$L15,'Expense Comp Data'!$I:$I)/SUMIF('Expense Comp Data'!$B:$B,"SqFoot_Total",'Expense Comp Data'!$I:$I),"No Comps") -> No Comps | P15: 0.1 | Q15: =IF(P15=0,O15,P15) -> 0.1 | R15: =Projection!BW98 -> 10580.7 | T15: 0 | U15: 0.025 | V15: =($T15*(1+U15))/Projection!$F$3 -> 0
A16: Managed | B16: Climate Controlled % | C16: =IFERROR(C15/C13, 0) -> 1 | E16: Starting Rates | H16: =IFERROR((C20-C30)/(C18-C24)*12,0) -> 0 | I16: =(('Rate Calculation'!R38*12)*0)+(1.55*12) -> 18.6 | J16: =I16 -> 18.6 | L16: 6200 | M16: Security Expense | N16: psf | O16: =IFERROR(SUMIF('Expense Comp Data'!$B:$B,Inputs!$L16,'Expense Comp Data'!$I:$I)/SUMIF('Expense Comp Data'!$B:$B,"SqFoot_Total",'Expense Comp Data'!$I:$I),"No Comps") -> No Comps | P16: 1e-12 | Q16: =IF(P16=0,O16,P16) -> 1e-12 | R16: =Projection!BW99 -> 1.05807e-07 | T16: 0 | U16: 0.025 | V16: =($T16*(1+U16))/Projection!$F$3 -> 0
A17: JV | B17: Starting Point | L17: 6205 | M17: Fire Alarm Monitoring | N17: psf | O17: =IFERROR(SUMIF('Expense Comp Data'!$B:$B,Inputs!$L17,'Expense Comp Data'!$I:$I)/SUMIF('Expense Comp Data'!$B:$B,"SqFoot_Total",'Expense Comp Data'!$I:$I),"No Comps") -> No Comps | P17: 0.01 | Q17: =IF(P17=0,O17,P17) -> 0.01 | R17: =Projection!BW100 -> 1058.07 | T17: 0 | U17: 0.025 | V17: =($T17*(1+U17))/Projection!$F$3 -> 0
B18: Occupied SF | C18: 0 | H18: IP Rate | I18: Rate Growth | J18: Avg Rate | M18: Total | R18: =Projection!BW101 -> 76181.04 | T18: 0 | U18: 0.025 | V18: =($T18*(1+U18))/Projection!$F$3 -> 0
B19: Occupied Units | C19: 0 | E19: 1 | H19: =Projection!BW34 -> 19.859233 | I19: 0.04 | J19: =Projection!BW30 -> 18.918678 | T19: 0 | U19: 0.025 | V19: =($T19*(1+U19))/Projection!$F$3 -> 0
B20: Projected Rent | C20: 0 | E20: 2 | H20: =Projection!BX34 -> 20.810242 | I20: 0.04 | J20: =Projection!BX30 -> 19.607006 | L20: R&M Expense | O20: Comp Data | P20: Override | Q20: Model | R20: Year 1 | T20: 0 | U20: 0.025 | V20: =($T20*(1+U20))/Projection!$F$3 -> 0
B21: Insurance Pen. | C21: 0 | E21: 3 | H21: =Projection!BY34 -> 21.794342 | I21: 0.04 | J21: =Projection!BY30 -> 20.320378 | L21: 6189 | M21: R&M Roof | N21: psf | O21: =IFERROR(SUMIF('Expense Comp Data'!$B:$B,Inputs!$L21,'Expense Comp Data'!$I:$I)/SUMIF('Expense Comp Data'!$B:$B,"SqFoot_Total",'Expense Comp Data'!$I:$I),"No Comps") -> No Comps | P21: =IF($V$29=0,0,Modeling!E36) -> 0.00945 | Q21: =IF(P21=0,O21,P21) -> 0.00945 | R21: =Projection!BW104 -> 299.96284 | T21: 0 | U21: 0.025 | V21: =($T21*(1+U21))/Projection!$F$3 -> 0
B22: Non-Storage Income | E22: 4 | H22: =Projection!BZ34 -> 22.648495 | I22: 0.04 | J22: =Projection!BZ30 -> 21.059704 | L22: 6192 | M22: Repairs & Maintenance | N22: psf | O22: =IFERROR(SUMIF('Expense Comp Data'!$B:$B,Inputs!$L22,'Expense Comp Data'!$I:$I)/SUMIF('Expense Comp Data'!$B:$B,"SqFoot_Total",'Expense Comp Data'!$I:$I),"No Comps") -> No Comps | P22: =IF($V$29=0,0,Modeling!E37) -> 0.0126 | Q22: =IF(P22=0,O22,P22) -> 0.0126 | R22: =Projection!BW105 -> 399.95046
B23: Non-Storage Total SF (Covered parking) | C23: 0 | E23: 5 | H23: =Projection!CA34 -> 23.666244 | I23: 0.04 | J23: =Projection!CA30 -> 21.82593 | L23: 6193 | M23: R&M Elevator | N23: psf | O23: =IFERROR(SUMIF('Expense Comp Data'!$B:$B,Inputs!$L23,'Expense Comp Data'!$I:$I)/SUMIF('Expense Comp Data'!$B:$B,"SqFoot_Total",'Expense Comp Data'!$I:$I),"No Comps") -> No Comps | P23: =IF(C62=FALSE,0,IF($V$29=0,0,Modeling!E38)) -> 0.0588 | Q23: =IF(P23=0,O23,P23) -> 0.0588 | R23: =Projection!BW106 -> 1866.4355 | T23: Dev Store Ref. Table | U23: ---------------------------------------------------->
B24: Non-Storage Occ SF (Covered parking) | C24: 0 | L24: 6194 | M24: R&M Doors | N24: psf | O24: =IFERROR(SUMIF('Expense Comp Data'!$B:$B,Inputs!$L24,'Expense Comp Data'!$I:$I)/SUMIF('Expense Comp Data'!$B:$B,"SqFoot_Total",'Expense Comp Data'!$I:$I),"No Comps") -> No Comps | P24: =IF($V$29=0,0,Modeling!E39) -> 0.01155 | Q24: =IF(P24=0,O24,P24) -> 0.01155 | R24: =Projection!BW107 -> 366.62125 | T24: R&M Phase-in Input
B25: Non-Covered Parking Total SF (removed from total) | C25: 0 | E25: Avg. Rate Increases % | I25: 0.12 | L25: 6195 | M25: R&M Gates | N25: psf | O25: =IFERROR(SUMIF('Expense Comp Data'!$B:$B,Inputs!$L25,'Expense Comp Data'!$I:$I)/SUMIF('Expense Comp Data'!$B:$B,"SqFoot_Total",'Expense Comp Data'!$I:$I),"No Comps") -> No Comps | P25: =IF($V$29=0,0,Modeling!E40) -> 0.013125 | Q25: =IF(P25=0,O25,P25) -> 0.013125 | R25: =Projection!BW108 -> 416.61506 | T25: Year 1 | V25: 0.3
B26: Non-Covered Parking Occ SF (removed from total) | C26: 0 | L26: 6196 | M26: R&M Golf Carts | N26: psf | O26: =IFERROR(SUMIF('Expense Comp Data'!$B:$B,Inputs!$L26,'Expense Comp Data'!$I:$I)/SUMIF('Expense Comp Data'!$B:$B,"SqFoot_Total",'Expense Comp Data'!$I:$I),"No Comps") -> No Comps | P26: =IF(C63=FALSE,0,IF($V$29=0,0,Modeling!E41)) -> 0 | Q26: =IF(P26=0,O26,P26) -> No Comps | R26: =Projection!BW109 -> 0 | T26: Year 2 | V26: 0.6
B27: Non-Storage Total Units | C27: 0 | E27: Non-Storage Income | L27: 6197 | M27: R&M Parking Lot | N27: psf | O27: =IFERROR(SUMIF('Expense Comp Data'!$B:$B,Inputs!$L27,'Expense Comp Data'!$I:$I)/SUMIF('Expense Comp Data'!$B:$B,"SqFoot_Total",'Expense Comp Data'!$I:$I),"No Comps") -> No Comps | P27: =IF($V$29=0,0,Modeling!E42) -> 0.0021 | Q27: =IF(P27=0,O27,P27) -> 0.0021 | R27: =Projection!BW110 -> 66.65841 | T27: Year 3 | V27: 1
B28: Non-Storage Occ Units | C28: 0 | E28: Modeling Methodology | I28: None | L28: 6198 | M28: R&M Cameras | N28: psf | O28: =IFERROR(SUMIF('Expense Comp Data'!$B:$B,Inputs!$L28,'Expense Comp Data'!$I:$I)/SUMIF('Expense Comp Data'!$B:$B,"SqFoot_Total",'Expense Comp Data'!$I:$I),"No Comps") -> No Comps | P28: =IF($V$29=0,0,Modeling!E43) -> 0.00525 | Q28: =IF(P28=0,O28,P28) -> 0.00525 | R28: =Projection!BW111 -> 166.64602
B29: Non-Storage GPI | C29: 0 | E29: Simple Annual Growth Rate | I29: 0.03 | L29: 6199 | M29: R&M HVAC | N29: psf | O29: =IFERROR(SUMIF('Expense Comp Data'!$B:$B,Inputs!$L29,'Expense Comp Data'!$I:$I)/SUMIF('Expense Comp Data'!$B:$B,"SqFoot_Total",'Expense Comp Data'!$I:$I),"No Comps") -> No Comps | P29: =IF($V$29=0,0,Modeling!E44) -> 0.0441 | Q29: =IF(P29=0,O29,P29) -> 0.0441 | R29: =Projection!BW112 -> 1399.8266 | T29: Input Stable R&M Total | V29: =0.21*C13 -> 22219.47
B30: Non-Storage Proj Rent | C30: 0 | E30: Leaseup: Starting Non-Storage GPI | I30: =C29 -> 0 | L30: 6201 | M30: R&M Fire Protection | N30: psf | O30: =IFERROR(SUMIF('Expense Comp Data'!$B:$B,Inputs!$L30,'Expense Comp Data'!$I:$I)/SUMIF('Expense Comp Data'!$B:$B,"SqFoot_Total",'Expense Comp Data'!$I:$I),"No Comps") -> No Comps | P30: =IF($V$29=0,0,Modeling!E45) -> 0.0231 | Q30: =IF(P30=0,O30,P30) -> 0.0231 | R30: =Projection!BW113 -> 733.24251
E31: Leaseup: # of Months to Stabilization | I31: 0 | L31: 6203 | M31: R&M Lighting/Electrical | N31: psf | O31: =IFERROR(SUMIF('Expense Comp Data'!$B:$B,Inputs!$L31,'Expense Comp Data'!$I:$I)/SUMIF('Expense Comp Data'!$B:$B,"SqFoot_Total",'Expense Comp Data'!$I:$I),"No Comps") -> No Comps | P31: =IF($V$29=0,0,Modeling!E46) -> 0.0168 | Q31: =IF(P31=0,O31,P31) -> 0.0168 | R31: =Projection!BW114 -> 533.26728 | U31: CC | V31: NON
B32: LT Growth Assumptions | E32: Leaseup: Fully-Stable Mtly Non-Storage Rental Income | I32: =I30*I10 -> 0 | L32: 6204 | M32: R&M Plumbing | N32: psf | O32: =IFERROR(SUMIF('Expense Comp Data'!$B:$B,Inputs!$L32,'Expense Comp Data'!$I:$I)/SUMIF('Expense Comp Data'!$B:$B,"SqFoot_Total",'Expense Comp Data'!$I:$I),"No Comps") -> No Comps | P32: =IF($V$29=0,0,Modeling!E47) -> 0.006825 | Q32: =IF(P32=0,O32,P32) -> 0.006825 | R32: =Projection!BW115 -> 216.63983 | T32: Rate
L33: 6206 | M33: R&M Exterior Bldg Repair | N33: psf | O33: =IFERROR(SUMIF('Expense Comp Data'!$B:$B,Inputs!$L33,'Expense Comp Data'!$I:$I)/SUMIF('Expense Comp Data'!$B:$B,"SqFoot_Total",'Expense Comp Data'!$I:$I),"No Comps") -> No Comps | P33: =IF($V$29=0,0,Modeling!E48) -> 0.0063 | Q33: =IF(P33=0,O33,P33) -> 0.0063 | R33: =Projection!BW116 -> 199.97523 | T33: CC% | U33: =$C$16 -> 1 | V33: =1-U33 -> 0
B34: LT Revenue Growth | C34: 0.04 | E34: Other Revenue Assumptions | L34: 6321 | M34: R&M Apartments | N34: psf | O34: =IFERROR(SUMIF('Expense Comp Data'!$B:$B,Inputs!$L34,'Expense Comp Data'!$I:$I)/SUMIF('Expense Comp Data'!$B:$B,"SqFoot_Total",'Expense Comp Data'!$I:$I),"No Comps") -> No Comps | P34: =IF(C64=FALSE,0,IF($V$29=0,O34,Modeling!E49)) -> 0 | Q34: =IF(P34=0,O34,P34) -> No Comps | R34: =Projection!BW117 -> 0 | T34: Blended | U34: =(U32*U33)+(V32*V33) -> 0
B35: Ann'l Expense Growth | C35: 0.025 | E35: Net Rental Income | H35: Comp | I35: Override | J35: Model | M35: Total | R35: =Projection!BW118 -> 6665.841
B36: Ann'l RE Tax Growth | C36: 0.01 | E36: 4700 | F36: Stable Discounts | G36: % of RI | H36: =IFERROR(SUMIF('Expense Comp Data'!$B:$B,Inputs!$E36,'Expense Comp Data'!$I:$I)/SUMIF('Expense Comp Data'!$B:$B,"ProjectedRent",'Expense Comp Data'!$I:$I),"No Comps") -> No Comps | I36: -0.025
B37: Management Contract | E37: WriteOffSum | F37: Write-offs | G37: % of RI | H37: =IFERROR(SUMIF('Expense Comp Data'!$B:$B,Inputs!$E37,'Expense Comp Data'!$I:$I)/SUMIF('Expense Comp Data'!$B:$B,"ProjectedRent",'Expense Comp Data'!$I:$I),"No Comps") -> No Comps | I37: -0.01 | J37: =MIN(IF(I37=0,H37,I37),-0.6%) -> -0.01 | L37: Other Operating Expense | O37: Comp Data | P37: Override | Q37: Model | R37: Year 1
B38: Sales Center | L38: 6122 | M38: Training | N38: per month | P38: 15 | Q38: =IF(P38=0,O38,P38) -> 15 | R38: =Projection!BW121 -> 180
B39: Management Fee Min | E39: Fee Income | H39: Comp | I39: Override | J39: Model | L39: 6152 | M39: Uniforms | N39: per EE | O39: =SUMIF('Expense Comp Data'!$B:$B,Inputs!$L39,'Expense Comp Data'!$I:$I)/12 -> 0 | P39: 175 | Q39: =IF(P39=0,O39,P39) -> 175 | R39: =Projection!BW122 -> 175
B40: Management Fee % | E40: 4281 | F40: Admin Fees | G40: per rental | H40: =IFERROR(SUMIF('Expense Comp Data'!$B:$B,$E40,'Expense Comp Data'!$I:$I)/SUMIF('Expense Comp Data'!$B:$B,"Rentals",'Expense Comp Data'!$I:$I),"No Comps") -> No Comps | I40: 15 | J40: =IF(I40=0,H40,I40) -> 15 | L40: 6162 | M40: Supplies | N40: per month | O40: =SUMIF('Expense Comp Data'!$B:$B,Inputs!$L40,'Expense Comp Data'!$I:$I)/12 -> 0 | P40: 0 | Q40: =IF(P40=0,O40,P40) -> 0 | R40: =Projection!BW125 -> 0
B41: 3PM Owner Insurance % | C41: 0.5 | E41: 4282 | F41: Late Fees | G41: % of RI | H41: =IFERROR(SUMIF('Expense Comp Data'!$B:$B,$E41,'Expense Comp Data'!$I:$I)/SUMIF('Expense Comp Data'!$B:$B,"ProjectedRent",'Expense Comp Data'!$I:$I),"No Comps") -> No Comps | I41: 0.001 | J41: =IF(I41=0,H41,I41) -> 0.001 | L41: 6163 | M41: Help Desk | N41: per month | P41: 43 | Q41: =IF(P41=0,O41,P41) -> 43 | R41: =Projection!BW126 -> 516 | T41: New Property Start-Up Costs
...

Sheet Projection
D2: Property Info | O2: =SUM(J4:O4) -> 0
D3: Storage SF: | F3: =Inputs!C13-Inputs!C23 -> 105807 | G3: Total SF w/ Parking: | H3: =F3+(Inputs!C23-Inputs!C25) -> 105807 | BF3: =IF(AND($H44="Leaseup",BF$8<=Inputs!$I$31),(Projection!BF44-Projection!BE44)/Inputs!$I$30*(Inputs!$C$23-Inputs!$C$25),0) -> 0
D4: Units: | F4: =Inputs!C14-Inputs!C27 -> 684 | G4: Total Units w/ Parking: | H4: =F4+Inputs!C27 -> 684 | J4: =IF(AND($H44="Leaseup",J$8<=Inputs!$I$31),(Projection!J44-Projection!I44)/Inputs!$I$30*(Inputs!$C$23-Inputs!$C$25),0) -> 0 | K4: =IF(AND($H44="Leaseup",K$8<=Inputs!$I$31),(Projection!K44-Projection!J44)/Inputs!$I$30*(Inputs!$C$23-Inputs!$C$25),0) -> 0 | L4: =IF(AND($H44="Leaseup",L$8<=Inputs!$I$31),(Projection!L44-Projection!K44)/Inputs!$I$30*(Inputs!$C$23-Inputs!$C$25),0) -> 0 | M4: =IF(AND($H44="Leaseup",M$8<=Inputs!$I$31),(Projection!M44-Projection!L44)/Inputs!$I$30*(Inputs!$C$23-Inputs!$C$25),0) -> 0 | N4: =IF(AND($H44="Leaseup",N$8<=Inputs!$I$31),(Projection!N44-Projection!M44)/Inputs!$I$30*(Inputs!$C$23-Inputs!$C$25),0) -> 0 | O4: =IF(AND($H44="Leaseup",O$8<=Inputs!$I$31),(Projection!O44-Projection!N44)/Inputs!$I$30*(Inputs!$C$23-Inputs!$C$25),0) -> 0 | P4: =IF(AND($H44="Leaseup",P$8<=Inputs!$I$31),(Projection!P44-Projection!O44)/Inputs!$I$30*(Inputs!$C$23-Inputs!$C$25),0) -> 0 | Q4: =IF(AND($H44="Leaseup",Q$8<=Inputs!$I$31),(Projection!Q44-Projection!P44)/Inputs!$I$30*(Inputs!$C$23-Inputs!$C$25),0) -> 0 | ... U4: =IF(AND($H44="Leaseup",U$8<=Inputs!$I$31),(Projection!U44-Projection!T44)/Inputs!$I$30*(Inputs!$C$23-Inputs!$C$25),0) -> 0
D5: Avg Unit SF: | F5: =F3/F4 -> 154.6886
D6: Summary Year | I6: 0 | J6: =IF(Inputs!$C$9>Projection!J9,0,ROUNDDOWN((IF(J9<Inputs!$C$9,0,I8+1)-1)/12,0)+1) -> 1 | K6: =IF(Inputs!$C$9>Projection!K9,0,ROUNDDOWN((IF(K9<Inputs!$C$9,0,J8+1)-1)/12,0)+1) -> 1 | L6: =IF(Inputs!$C$9>Projection!L9,0,ROUNDDOWN((IF(L9<Inputs!$C$9,0,K8+1)-1)/12,0)+1) -> 1 | M6: =IF(Inputs!$C$9>Projection!M9,0,ROUNDDOWN((IF(M9<Inputs!$C$9,0,L8+1)-1)/12,0)+1) -> 1 | N6: =IF(Inputs!$C$9>Projection!N9,0,ROUNDDOWN((IF(N9<Inputs!$C$9,0,M8+1)-1)/12,0)+1) -> 1 | O6: =IF(Inputs!$C$9>Projection!O9,0,ROUNDDOWN((IF(O9<Inputs!$C$9,0,N8+1)-1)/12,0)+1) -> 1 | P6: =IF(Inputs!$C$9>Projection!P9,0,ROUNDDOWN((IF(P9<Inputs!$C$9,0,O8+1)-1)/12,0)+1) -> 1 | Q6: =IF(Inputs!$C$9>Projection!Q9,0,ROUNDDOWN((IF(Q9<Inputs!$C$9,0,P8+1)-1)/12,0)+1) -> 1 | ... BU6: =IF(Inputs!$C$9>Projection!BU9,0,ROUNDDOWN((IF(BU9<Inputs!$C$9,0,BT8+1)-1)/12,0)+1) -> 6
D7: Year: | J7: 1 | K7: 1 | L7: 1 | M7: 1 | N7: 1 | O7: 1 | P7: 1 | Q7: 1 | R7: 1 | S7: 1 | T7: 1 | U7: 1 | V7: 2 | W7: 2 | X7: 2 | Y7: 2 | Z7: 2 | AA7: 2 | AB7: 2 | AC7: 2 | AD7: 2 | AE7: 2 | AF7: 2 | AG7: 2 | AH7: 3 | AI7: 3 | AJ7: 3 | AK7: 3 | AL7: 3 | AM7: 3 | AN7: 3 | AO7: 3 | AP7: 3 | AQ7: 3 | AR7: 3 | AS7: 3 | AT7: 4 | AU7: 4 | AV7: 4 | AW7: 4 | AX7: 4 | AY7: 4 | AZ7: 4 | BA7: 4 | BB7: 4 | BC7: 4 | BD7: 4 | BE7: 4 | BF7: 5 | BG7: 5 | BH7: 5 | BI7: 5 | BJ7: 5 | BK7: 5 | BL7: 5 | BM7: 5 | BN7: 5 | BO7: 5 | BP7: 5 | BQ7: 5 | BR7: 6 | BS7: 6 | BT7: 6 | BU7: 6 | BW7: 1 | BX7: 2 | BY7: 3 | BZ7: 4 | CA7: 5 | CB7: 6 | CC7: 7
D8: Total Projection Month: | J8: =IF(J9<Inputs!$C$9,0,I8+1) -> 1 | K8: =IF(K9<Inputs!$C$9,0,J8+1) -> 2 | L8: =IF(L9<Inputs!$C$9,0,K8+1) -> 3 | M8: =IF(M9<Inputs!$C$9,0,L8+1) -> 4 | N8: =IF(N9<Inputs!$C$9,0,M8+1) -> 5 | O8: =IF(O9<Inputs!$C$9,0,N8+1) -> 6 | P8: =IF(P9<Inputs!$C$9,0,O8+1) -> 7 | Q8: =IF(Q9<Inputs!$C$9,0,P8+1) -> 8 | ... BU8: =IF(BU9<Inputs!$C$9,0,BT8+1) -> 64
A9: =$F$2 -> 0 | H9: Mkt Rate | I9: In-Place | J9: =Inputs!$C$8 -> 46053 | K9: =EOMONTH(J9,1) -> 46081 | L9: =EOMONTH(K9,1) -> 46112 | M9: =EOMONTH(L9,1) -> 46142 | N9: =EOMONTH(M9,1) -> 46173 | O9: =EOMONTH(N9,1) -> 46203 | P9: =EOMONTH(O9,1) -> 46234 | Q9: =EOMONTH(P9,1) -> 46265 | R9: =EOMONTH(Q9,1) -> 46295 | ... BU9: =EOMONTH(BT9,1) -> 47968 | BW9: 1 | BX9: 2 | BY9: 3 | BZ9: 4 | CA9: 5 | CB9: 6 | CC9: 7 | CD9: 8 | CE9: 9 | CF9: 10 | CG9: 11 | CH9: 12 | CI9: 13 | CJ9: 14 | CK9: 15
A10: =$F$2 -> 0
A11: =$F$2 -> 0 | D11: Revenue Forecast | BW11: Revenue Forecast
A12: =$F$2 -> 0 | D12: Occupancy | BW12: =D12 -> Occupancy
A13: =$F$2 -> 0 | F13: Automated Occupancy | I13: =(Inputs!C18-Inputs!C24)/(Inputs!C13-Inputs!C23) -> 0 | J13: =IF(J$7>=Inputs!$I$12,Inputs!$I$13+VLOOKUP(MONTH(J$9),Modeling!$B$4:$G$16,4,FALSE),RentalsVacates!G2+(VLOOKUP(J$7,Inputs!$G$4:$I$10,3,FALSE)-VLOOKUP(J$7-1,Inputs!$G$4:$I$10,3,FALSE))/12*VLOOKUP(MONTH(J$9),Modeling!$B$4:$I$16,8,FALSE)+IF(Inputs!$I$6<60%,VLOOKUP(Projection!J$8,Modeling!$B$4:$K$16,9,FALSE)+VLOOKUP(MONTH(J$9),Modeling!$B$4:$K$16,10,FALSE),0)) -> 0.021821417 | K13: =IF(K$7>=Inputs!$I$12,Inputs!$I$13+VLOOKUP(MONTH(K$9),Modeling!$B$4:$G$16,4,FALSE),RentalsVacates!H2+(VLOOKUP(K$7,Inputs!$G$4:$I$10,3,FALSE)-VLOOKUP(K$7-1,Inputs!$G$4:$I$10,3,FALSE))/12*VLOOKUP(MONTH(K$9),Modeling!$B$4:$I$16,8,FALSE)+IF(Inputs!$I$6<60%,VLOOKUP(Projection!K$8,Modeling!$B$4:$K$16,9,FALSE)+VLOOKUP(MONTH(K$9),Modeling!$B$4:$K$16,10,FALSE),0)) -> 0.043379585 | L13: =IF(L$7>=Inputs!$I$12,Inputs!$I$13+VLOOKUP(MONTH(L$9),Modeling!$B$4:$G$16,4,FALSE),RentalsVacates!I2+(VLOOKUP(L$7,Inputs!$G$4:$I$10,3,FALSE)-VLOOKUP(L$7-1,Inputs!$G$4:$I$10,3,FALSE))/12*VLOOKUP(MONTH(L$9),Modeling!$B$4:$I$16,8,FALSE)+IF(Inputs!$I$6<60%,VLOOKUP(Projection!L$8,Modeling!$B$4:$K$16,9,FALSE)+VLOOKUP(MONTH(L$9),Modeling!$B$4:$K$16,10,FALSE),0)) -> 0.073093854 | M13: =IF(M$7>=Inputs!$I$12,Inputs!$I$13+VLOOKUP(MONTH(M$9),Modeling!$B$4:$G$16,4,FALSE),RentalsVacates!J2+(VLOOKUP(M$7,Inputs!$G$4:$I$10,3,FALSE)-VLOOKUP(M$7-1,Inputs!$G$4:$I$10,3,FALSE))/12*VLOOKUP(MONTH(M$9),Modeling!$B$4:$I$16,8,FALSE)+IF(Inputs!$I$6<60%,VLOOKUP(Projection!M$8,Modeling!$B$4:$K$16,9,FALSE)+VLOOKUP(MONTH(M$9),Modeling!$B$4:$K$16,10,FALSE),0)) -> 0.10328732 | N13: =IF(N$7>=Inputs!$I$12,Inputs!$I$13+VLOOKUP(MONTH(N$9),Modeling!$B$4:$G$16,4,FALSE),RentalsVacates!K2+(VLOOKUP(N$7,Inputs!$G$4:$I$10,3,FALSE)-VLOOKUP(N$7-1,Inputs!$G$4:$I$10,3,FALSE))/12*VLOOKUP(MONTH(N$9),Modeling!$B$4:$I$16,8,FALSE)+IF(Inputs!$I$6<60%,VLOOKUP(Projection!N$8,Modeling!$B$4:$K$16,9,FALSE)+VLOOKUP(MONTH(N$9),Modeling!$B$4:$K$16,10,FALSE),0)) -> 0.14958765 | O13: =IF(O$7>=Inputs!$I$12,Inputs!$I$13+VLOOKUP(MONTH(O$9),Modeling!$B$4:$G$16,4,FALSE),RentalsVacates!L2+(VLOOKUP(O$7,Inputs!$G$4:$I$10,3,FALSE)-VLOOKUP(O$7-1,Inputs!$G$4:$I$10,3,FALSE))/12*VLOOKUP(MONTH(O$9),Modeling!$B$4:$I$16,8,FALSE)+IF(Inputs!$I$6<60%,VLOOKUP(Projection!O$8,Modeling!$B$4:$K$16,9,FALSE)+VLOOKUP(MONTH(O$9),Modeling!$B$4:$K$16,10,FALSE),0)) -> 0.1878091 | P13: =IF(P$7>=Inputs!$I$12,Inputs!$I$13+VLOOKUP(MONTH(P$9),Modeling!$B$4:$G$16,4,FALSE),RentalsVacates!M2+(VLOOKUP(P$7,Inputs!$G$4:$I$10,3,FALSE)-VLOOKUP(P$7-1,Inputs!$G$4:$I$10,3,FALSE))/12*VLOOKUP(MONTH(P$9),Modeling!$B$4:$I$16,8,FALSE)+IF(Inputs!$I$6<60%,VLOOKUP(Projection!P$8,Modeling!$B$4:$K$16,9,FALSE)+VLOOKUP(MONTH(P$9),Modeling!$B$4:$K$16,10,FALSE),0)) -> 0.22122481 | Q13: =IF(Q$7>=Inputs!$I$12,Inputs!$I$13+VLOOKUP(MONTH(Q$9),Modeling!$B$4:$G$16,4,FALSE),RentalsVacates!N2+(VLOOKUP(Q$7,Inputs!$G$4:$I$10,3,FALSE)-VLOOKUP(Q$7-1,Inputs!$G$4:$I$10,3,FALSE))/12*VLOOKUP(MONTH(Q$9),Modeling!$B$4:$I$16,8,FALSE)+IF(Inputs!$I$6<60%,VLOOKUP(Projection!Q$8,Modeling!$B$4:$K$16,9,FALSE)+VLOOKUP(MONTH(Q$9),Modeling!$B$4:$K$16,10,FALSE),0)) -> 0.2464521 | ... U13: =IF(U$7>=Inputs!$I$12,Inputs!$I$13+VLOOKUP(MONTH(U$9),Modeling!$B$4:$G$16,4,FALSE),RentalsVacates!R2+(VLOOKUP(U$7,Inputs!$G$4:$I$10,3,FALSE)-VLOOKUP(U$7-1,Inputs!$G$4:$I$10,3,FALSE))/12*VLOOKUP(MONTH(U$9),Modeling!$B$4:$I$16,8,FALSE)+IF(Inputs!$I$6<60%,VLOOKUP(Projection!U$8,Modeling!$B$4:$K$16,9,FALSE)+VLOOKUP(MONTH(U$9),Modeling!$B$4:$K$16,10,FALSE),0)) -> 0.33 | V13: =IF(V$7>=Inputs!$I$12,Inputs!$I$13+VLOOKUP(MONTH(V$9),Modeling!$B$4:$G$16,4,FALSE),RentalsVacates!S2+(VLOOKUP(V$7,Inputs!$G$4:$I$10,3,FALSE)-VLOOKUP(V$7-1,Inputs!$G$4:$I$10,3,FALSE))/12*VLOOKUP(MONTH(V$9),Modeling!$B$4:$I$16,8,FALSE)+VLOOKUP(MONTH(V$9),Modeling!$B$4:$K$16,10,FALSE)) -> 0.35314393 | W13: =IF(W$7>=Inputs!$I$12,Inputs!$I$13+VLOOKUP(MONTH(W$9),Modeling!$B$4:$G$16,4,FALSE),RentalsVacates!T2+(VLOOKUP(W$7,Inputs!$G$4:$I$10,3,FALSE)-VLOOKUP(W$7-1,Inputs!$G$4:$I$10,3,FALSE))/12*VLOOKUP(MONTH(W$9),Modeling!$B$4:$I$16,8,FALSE)+VLOOKUP(MONTH(W$9),Modeling!$B$4:$K$16,10,FALSE)) -> 0.37600865 | X13: =IF(X$7>=Inputs!$I$12,Inputs!$I$13+VLOOKUP(MONTH(X$9),Modeling!$B$4:$G$16,4,FALSE),RentalsVacates!U2+(VLOOKUP(X$7,Inputs!$G$4:$I$10,3,FALSE)-VLOOKUP(X$7-1,Inputs!$G$4:$I$10,3,FALSE))/12*VLOOKUP(MONTH(X$9),Modeling!$B$4:$I$16,8,FALSE)+VLOOKUP(MONTH(X$9),Modeling!$B$4:$K$16,10,FALSE)) -> 0.40752378 | Y13: =IF(Y$7>=Inputs!$I$12,Inputs!$I$13+VLOOKUP(MONTH(Y$9),Modeling!$B$4:$G$16,4,FALSE),RentalsVacates!V2+(VLOOKUP(Y$7,Inputs!$G$4:$I$10,3,FALSE)-VLOOKUP(Y$7-1,Inputs!$G$4:$I$10,3,FALSE))/12*VLOOKUP(MONTH(Y$9),Modeling!$B$4:$I$16,8,FALSE)+VLOOKUP(MONTH(Y$9),Modeling!$B$4:$K$16,10,FALSE)) -> 0.43954716 | Z13: =IF(Z$7>=Inputs!$I$12,Inputs!$I$13+VLOOKUP(MONTH(Z$9),Modeling!$B$4:$G$16,4,FALSE),RentalsVacates!W2+(VLOOKUP(Z$7,Inputs!$G$4:$I$10,3,FALSE)-VLOOKUP(Z$7-1,Inputs!$G$4:$I$10,3,FALSE))/12*VLOOKUP(MONTH(Z$9),Modeling!$B$4:$I$16,8,FALSE)+VLOOKUP(MONTH(Z$9),Modeling!$B$4:$K$16,10,FALSE)) -> 0.48865357 | AA13: =IF(AA$7>=Inputs!$I$12,Inputs!$I$13+VLOOKUP(MONTH(AA$9),Modeling!$B$4:$G$16,4,FALSE),RentalsVacates!X2+(VLOOKUP(AA$7,Inputs!$G$4:$I$10,3,FALSE)-VLOOKUP(AA$7-1,Inputs!$G$4:$I$10,3,FALSE))/12*VLOOKUP(MONTH(AA$9),Modeling!$B$4:$I$16,8,FALSE)+VLOOKUP(MONTH(AA$9),Modeling!$B$4:$K$16,10,FALSE)) -> 0.52919147 | AB13: =IF(AB$7>=Inputs!$I$12,Inputs!$I$13+VLOOKUP(MONTH(AB$9),Modeling!$B$4:$G$16,4,FALSE),RentalsVacates!Y2+(VLOOKUP(AB$7,Inputs!$G$4:$I$10,3,FALSE)-VLOOKUP(AB$7-1,Inputs!$G$4:$I$10,3,FALSE))/12*VLOOKUP(MONTH(AB$9),Modeling!$B$4:$I$16,8,FALSE)+VLOOKUP(MONTH(AB$9),Modeling!$B$4:$K$16,10,FALSE)) -> 0.56463238 | AC13: =IF(AC$7>=Inputs!$I$12,Inputs!$I$13+VLOOKUP(MONTH(AC$9),Modeling!$B$4:$G$16,4,FALSE),RentalsVacates!Z2+(VLOOKUP(AC$7,Inputs!$G$4:$I$10,3,FALSE)-VLOOKUP(AC$7-1,Inputs!$G$4:$I$10,3,FALSE))/12*VLOOKUP(MONTH(AC$9),Modeling!$B$4:$I$16,8,FALSE)+VLOOKUP(MONTH(AC$9),Modeling!$B$4:$K$16,10,FALSE)) -> 0.59138859 | ... BU13: =IF(BU$7>=Inputs!$I$12,Inputs!$I$13+VLOOKUP(MONTH(BU$9),Modeling!$B$4:$G$16,4,FALSE),RentalsVacates!BR2+(VLOOKUP(BU$7,Inputs!$G$4:$I$10,3,FALSE)-VLOOKUP(BU$7-1,Inputs!$G$4:$I$10,3,FALSE))/12*VLOOKUP(MONTH(BU$9),Modeling!$B$4:$I$16,8,FALSE)+VLOOKUP(MONTH(BU$9),Modeling!$B$4:$K$16,10,FALSE)) -> 0.91566667 | BW13: =AVERAGEIF($J$6:$BU$6,BW$9,$K13:$BU13) -> 0.21502763 | BX13: =AVERAGEIF($J$6:$BU$6,BX$9,$K13:$BU13) -> 0.55733657 | BY13: =AVERAGEIF($J$6:$BU$6,BY$9,$K13:$BU13) -> 0.83395329 | BZ13: =AVERAGEIF($J$6:$BU$6,BZ$9,$K13:$BU13) -> 0.92 | CA13: =AVERAGEIF($J$6:$BU$6,CA$9,$K13:$BU13) -> 0.92 | CB13: =CA13 -> 0.92 | CC13: =CB13 -> 0.92 | CD13: =CC13 -> 0.92 | CE13: =CD13 -> 0.92 | CF13: =CE13 -> 0.92 | CG13: =CF13 -> 0.92 | CH13: =CG13 -> 0.92 | CI13: =CH13 -> 0.92 | ... CK13: =CJ13 -> 0.92
A14: =$F$2 -> 0 | F14: Automated Rentals | J14: =RentalsVacates!H5 -> 14.925849 | K14: =RentalsVacates!I5 -> 14.745787 | L14: =RentalsVacates!J5 -> 21.810253 | M14: =RentalsVacates!K5 -> 23.883929 | N14: =RentalsVacates!L5 -> 36.70985 | O14: =RentalsVacates!M5 -> 34.292549 | P14: =RentalsVacates!N5 -> 33.8332 | Q14: =RentalsVacates!O5 -> 32.233434 | ... BU14: =RentalsVacates!BS5 -> 27.402977 | BW14: =SUMIF($J$6:$BU$6,BW$9,$J14:$BU14) -> 333.57223 | BX14: =SUMIF($J$6:$BU$6,BX$9,$J14:$BU14) -> 551.64635 | BY14: =SUMIF($J$6:$BU$6,BY$9,$J14:$BU14) -> 606.19768 | BZ14: =SUMIF($J$6:$BU$6,BZ$9,$J14:$BU14) -> 443.29988 | CA14: =SUMIF($J$6:$BU$6,CA$9,$J14:$BU14) -> 414.61604 | CB14: =CA14 -> 414.61604 | CC14: =CB14 -> 414.61604 | CD14: =CC14 -> 414.61604 | CE14: =CD14 -> 414.61604 | CF14: =CE14 -> 414.61604 | CG14: =CF14 -> 414.61604 | CH14: =CG14 -> 414.61604 | CI14: =CH14 -> 414.61604 | ... CK14: =CJ14 -> 414.61604
A15: =$F$2 -> 0 | F15: Automated Vacates | J15: =RentalsVacates!H6 -> 0 | K15: =RentalsVacates!I6 -> 0 | L15: =RentalsVacates!J6 -> -1.4856926 | M15: =RentalsVacates!K6 -> -3.2315988 | N15: =RentalsVacates!L6 -> -5.0404209 | O15: =RentalsVacates!M6 -> -8.1490822 | P15: =RentalsVacates!N6 -> -10.976852 | Q15: =RentalsVacates!O6 -> -14.977967 | ... BU15: =RentalsVacates!BS6 -> -23.982977 | BW15: =SUMIF($J$6:$BU$6,BW$9,$J15:$BU15) -> -107.85223 | BX15: =SUMIF($J$6:$BU$6,BX$9,$J15:$BU15) -> -312.24635 | BY15: =SUMIF($J$6:$BU$6,BY$9,$J15:$BU15) -> -442.03768 | BZ15: =SUMIF($J$6:$BU$6,BZ$9,$J15:$BU15) -> -451.73588 | CA15: =SUMIF($J$6:$BU$6,CA$9,$J15:$BU15) -> -414.61604 | CB15: =CA15 -> -414.61604 | CC15: =CB15 -> -414.61604 | CD15: =CC15 -> -414.61604 | CE15: =CD15 -> -414.61604 | CF15: =CE15 -> -414.61604 | CG15: =CF15 -> -414.61604 | CH15: =CG15 -> -414.61604 | CI15: =CH15 -> -414.61604 | ... CK15: =CJ15 -> -414.61604
A16: =$F$2 -> 0 | F16: Vacate Change | J16: 0 | K16: 0 | L16: 0 | M16: 0 | N16: 0 | O16: 0 | P16: 0 | Q16: 0 | R16: 0 | S16: 0 | T16: 0 | U16: 0 | V16: 0 | W16: 0 | X16: 0 | Y16: 0 | Z16: 0 | AA16: 0 | AB16: 0 | AC16: 0 | AD16: 0 | AE16: 0 | AF16: 0 | AG16: 0 | AH16: 0 | AI16: 0 | AJ16: 0 | AK16: 0 | AL16: 0 | AM16: 0 | AN16: 0 | AO16: 0 | AP16: 0 | AQ16: 0 | AR16: 0 | AS16: 0 | AT16: 0 | AU16: 0 | AV16: 0 | AW16: 0 | AX16: 0 | AY16: 0 | AZ16: 0 | BA16: 0 | BB16: 0 | BC16: 0 | BD16: 0 | BE16: 0 | BF16: 0 | BG16: 0 | BH16: 0 | BI16: 0 | BJ16: 0 | BK16: 0 | BL16: 0 | BM16: 0 | BN16: 0 | BO16: 0 | BP16: 0 | BQ16: 0 | BR16: 0 | BS16: 0 | BT16: 0 | BU16: 0
A18: =$F$2 -> 0 | B18: MI | F18: Move In's | J18: =J14 -> 14.925849 | K18: =K14 -> 14.745787 | L18: =L14 -> 21.810253 | M18: =M14 -> 23.883929 | N18: =N14 -> 36.70985 | O18: =O14 -> 34.292549 | P18: =P14 -> 33.8332 | Q18: =Q14 -> 32.233434 | ... BU18: =BU14 -> 27.402977 | BW18: =SUMIF($J$6:$BU$6,BW$9,$J18:$BU18) -> 333.57223 | BX18: =SUMIF($J$6:$BU$6,BX$9,$J18:$BU18) -> 551.64635 | BY18: =SUMIF($J$6:$BU$6,BY$9,$J18:$BU18) -> 606.19768 | BZ18: =SUMIF($J$6:$BU$6,BZ$9,$J18:$BU18) -> 443.29988 | CA18: =SUMIF($J$6:$BU$6,CA$9,$J18:$BU18) -> 414.61604 | CB18: =CA18 -> 414.61604 | CC18: =CB18 -> 414.61604 | CD18: =CC18 -> 414.61604 | CE18: =CD18 -> 414.61604 | CF18: =CE18 -> 414.61604 | CG18: =CF18 -> 414.61604 | CH18: =CG18 -> 414.61604 | CI18: =CH18 -> 414.61604 | ... CK18: =CJ18 -> 414.61604
A19: =$F$2 -> 0 | B19: MO | F19: Move Out's | J19: =Monthly!D26/Projection!$F$5 -> 0 | K19: =Monthly!E26/Projection!$F$5 -> 0 | L19: =Monthly!F26/Projection!$F$5 -> -1.4856926 | M19: =Monthly!G26/Projection!$F$5 -> -3.2315988 | N19: =Monthly!H26/Projection!$F$5 -> -5.0404209 | O19: =Monthly!I26/Projection!$F$5 -> -8.1490822 | P19: =Monthly!J26/Projection!$F$5 -> -10.976852 | Q19: =Monthly!K26/Projection!$F$5 -> -14.977967 | ... BU19: =Monthly!BO26/Projection!$F$5 -> -23.982977 | BW19: =SUMIF($J$6:$BU$6,BW$9,$J19:$BU19) -> -107.85223 | BX19: =SUMIF($J$6:$BU$6,BX$9,$J19:$BU19) -> -312.24635 | BY19: =SUMIF($J$6:$BU$6,BY$9,$J19:$BU19) -> -442.03768 | BZ19: =SUMIF($J$6:$BU$6,BZ$9,$J19:$BU19) -> -451.73588 | CA19: =SUMIF($J$6:$BU$6,CA$9,$J19:$BU19) -> -414.61604 | CB19: =CA19 -> -414.61604 | CC19: =CB19 -> -414.61604 | CD19: =CC19 -> -414.61604 | CE19: =CD19 -> -414.61604 | CF19: =CE19 -> -414.61604 | CG19: =CF19 -> -414.61604 | CH19: =CG19 -> -414.61604 | CI19: =CH19 -> -414.61604 | ... CK19: =CJ19 -> -414.61604
A20: =$F$2 -> 0 | B20: Net | F20: Net Rentals | J20: =J18+J19 -> 14.925849 | K20: =K18+K19 -> 14.745787 | L20: =L18+L19 -> 20.32456 | M20: =M18+M19 -> 20.65233 | N20: =N18+N19 -> 31.669429 | O20: =O18+O19 -> 26.143467 | P20: =P18+P19 -> 22.856348 | Q20: =Q18+Q19 -> 17.255467 | ... BU20: =BU18+BU19 -> 3.42 | BW20: =SUMIF($J$6:$BU$6,BW$9,$J20:$BU20) -> 225.72 | BX20: =SUMIF($J$6:$BU$6,BX$9,$J20:$BU20) -> 239.4 | BY20: =SUMIF($J$6:$BU$6,BY$9,$J20:$BU20) -> 164.16 | BZ20: =SUMIF($J$6:$BU$6,BZ$9,$J20:$BU20) -> -8.436 | CA20: =SUMIF($J$6:$BU$6,CA$9,$J20:$BU20) -> 0 | CB20: =CA20 -> 0 | CC20: =CB20 -> 0 | CD20: =CC20 -> 0 | CE20: =CD20 -> 0 | CF20: =CE20 -> 0 | CG20: =CF20 -> 0 | CH20: =CG20 -> 0 | CI20: =CH20 -> 0 | ... CK20: =CJ20 -> 0
A21: =$F$2 -> 0 | B21: RentEnd | F21: Ending Occupied Units | I21: =(Inputs!C19-Inputs!C28) -> 0 | J21: =I21+J20 -> 14.925849 | K21: =J21+K20 -> 29.671636 | L21: =K21+L20 -> 49.996196 | M21: =L21+M20 -> 70.648527 | N21: =M21+N20 -> 102.31796 | O21: =N21+O20 -> 128.46142 | P21: =O21+P20 -> 151.31777 | Q21: =P21+Q20 -> 168.57324 | ... BU21: =BT21+BU20 -> 626.316 | BW21: =SUMIF($J$6:$BU$6,BW$9,$J21:$BU21)/12 -> 128.19352 | BX21: =SUMIF($J$6:$BU$6,BX$9,$J21:$BU21)/12 -> 361.68282 | BY21: =SUMIF($J$6:$BU$6,BY$9,$J21:$BU21)/12 -> 558.35165 | BZ21: =SUMIF($J$6:$BU$6,BZ$9,$J21:$BU21)/12 -> 629.28 | CA21: =SUMIF($J$6:$BU$6,CA$9,$J21:$BU21)/12 -> 629.28
A22: =$F$2 -> 0 | J22: =J15-J19 -> 0 | K22: =K15-K19 -> 0 | L22: =L15-L19 -> 0 | M22: =M15-M19 -> 0 | N22: =N15-N19 -> 0 | O22: =O15-O19 -> 0 | P22: =P15-P19 -> 0 | Q22: =Q15-Q19 -> 0 | ... BU22: =BU15-BU19 -> 0
A23: =$F$2 -> 0 | B23: StorageSF | F23: Storage Square Feet Rented | I23: =(Inputs!C18-Inputs!C24) -> 0 | J23: =I23+J$20*$F$5 -> 2308.8587 | K23: =J23+K$20*$F$5 -> 4589.8637 | L23: =K23+L$20*$F$5 -> 7733.8414 | M23: =L23+M$20*$F$5 -> 10928.521 | N23: =M23+N$20*$F$5 -> 15827.421 | O23: =N23+O$20*$F$5 -> 19871.517 | P23: =O23+P$20*$F$5 -> 23407.134 | Q23: =P23+Q$20*$F$5 -> 26076.358 | ... BU23: =BT23+BU$20*$F$5 -> 96883.943 | BW23: =SUMIF($J$6:$BU$6,BW$9,$J23:$BU23)/12 -> 19830.076 | BX23: =SUMIF($J$6:$BU$6,BX$9,$J23:$BU23)/12 -> 55948.208 | BY23: =SUMIF($J$6:$BU$6,BY$9,$J23:$BU23)/12 -> 86370.633 | BZ23: =SUMIF($J$6:$BU$6,BZ$9,$J23:$BU23)/12 -> 97342.44 | CA23: =SUMIF($J$6:$BU$6,CA$9,$J23:$BU23)/12 -> 97342.44 | CB23: =CA23 -> 97342.44 | CC23: =CB23 -> 97342.44 | CD23: =CC23 -> 97342.44 | CE23: =CD23 -> 97342.44 | CF23: =CE23 -> 97342.44 | CG23: =CF23 -> 97342.44 | CH23: =CG23 -> 97342.44 | CI23: =CH23 -> 97342.44 | ... CK23: =CJ23 -> 97342.44
A24: =$F$2 -> 0 | B24: StorageOcc | F24: Storage SF Occupancy | I24: =(Inputs!C18-Inputs!C24)/(Inputs!C13-Inputs!C23) -> 0 | J24: =J23/$F$3 -> 0.021821417 | K24: =K23/$F$3 -> 0.043379585 | L24: =L23/$F$3 -> 0.073093854 | M24: =M23/$F$3 -> 0.10328732 | N24: =N23/$F$3 -> 0.14958765 | O24: =O23/$F$3 -> 0.1878091 | P24: =P23/$F$3 -> 0.22122481 | Q24: =Q23/$F$3 -> 0.2464521 | ... BU24: =BU23/$F$3 -> 0.91566667 | BW24: =AVERAGEIF($J$6:$BU$6,BW$9,$J24:$BU24) -> 0.18741743 | BX24: =AVERAGEIF($J$6:$BU$6,BX$9,$J24:$BU24) -> 0.52877606 | BY24: =AVERAGEIF($J$6:$BU$6,BY$9,$J24:$BU24) -> 0.81630358 | BZ24: =AVERAGEIF($J$6:$BU$6,BZ$9,$J24:$BU24) -> 0.92 | CA24: =AVERAGEIF($J$6:$BU$6,CA$9,$J24:$BU24) -> 0.92 | CB24: =CA24 -> 0.92 | CC24: =CB24 -> 0.92 | CD24: =CC24 -> 0.92 | CE24: =CD24 -> 0.92 | CF24: =CE24 -> 0.92 | CG24: =CF24 -> 0.92 | CH24: =CG24 -> 0.92 | CI24: =CH24 -> 0.92 | ... CK24: =CJ24 -> 0.92
A25: =$F$2 -> 0 | B25: ='7 Year Projection-Expanded'!A18 -> SFRent | F25: Total SF Rented | I25: =I23+Inputs!C24-Inputs!C26 -> 0 | J25: =J23+J46 -> 2308.8587 | K25: =K23+K46 -> 4589.8637 | L25: =L23+L46 -> 7733.8414 | M25: =M23+M46 -> 10928.521 | N25: =N23+N46 -> 15827.421 | O25: =O23+O46 -> 19871.517 | P25: =P23+P46 -> 23407.134 | Q25: =Q23+Q46 -> 26076.358 | ... BU25: =BU23+BU46 -> 96883.943 | BW25: =AVERAGEIF($J$6:$BU$6,BW$9,$J25:$BU25) -> 19830.076 | BX25: =AVERAGEIF($J$6:$BU$6,BX$9,$J25:$BU25) -> 55948.208 | BY25: =AVERAGEIF($J$6:$BU$6,BY$9,$J25:$BU25) -> 86370.633 | BZ25: =AVERAGEIF($J$6:$BU$6,BZ$9,$J25:$BU25) -> 97342.44 | CA25: =AVERAGEIF($J$6:$BU$6,CA$9,$J25:$BU25) -> 97342.44 | CB25: =CA25 -> 97342.44 | CC25: =CB25 -> 97342.44 | CD25: =CC25 -> 97342.44 | CE25: =CD25 -> 97342.44 | CF25: =CE25 -> 97342.44 | CG25: =CF25 -> 97342.44 | CH25: =CG25 -> 97342.44 | CI25: =CH25 -> 97342.44 | ... CK25: =CJ25 -> 97342.44
A26: =$F$2 -> 0 | B26: ='7 Year Projection-Expanded'!A19 -> SFOcc% | F26: Total SF Occupancy | I26: =I25/$H$3 -> 0 | J26: =J25/$H$3 -> 0.021821417 | K26: =K25/$H$3 -> 0.043379585 | L26: =L25/$H$3 -> 0.073093854 | M26: =M25/$H$3 -> 0.10328732 | N26: =N25/$H$3 -> 0.14958765 | O26: =O25/$H$3 -> 0.1878091 | P26: =P25/$H$3 -> 0.22122481 | ... BU26: =BU25/$H$3 -> 0.91566667 | BW26: =AVERAGEIF($J$6:$BU$6,BW$9,$J26:$BU26) -> 0.18741743 | BX26: =AVERAGEIF($J$6:$BU$6,BX$9,$J26:$BU26) -> 0.52877606 | BY26: =AVERAGEIF($J$6:$BU$6,BY$9,$J26:$BU26) -> 0.81630358 | BZ26: =AVERAGEIF($J$6:$BU$6,BZ$9,$J26:$BU26) -> 0.92 | CA26: =AVERAGEIF($J$6:$BU$6,CA$9,$J26:$BU26) -> 0.92 | CB26: =CA26 -> 0.92 | CC26: =CB26 -> 0.92 | CD26: =CC26 -> 0.92 | CE26: =CD26 -> 0.92 | CF26: =CE26 -> 0.92 | CG26: =CF26 -> 0.92 | CH26: =CG26 -> 0.92 | CI26: =CH26 -> 0.92 | ... CK26: =CJ26 -> 0.92
A27: =$F$2 -> 0
A28: =$F$2 -> 0 | D28: Rates | BW28: Rates
A29: =$F$2 -> 0 | F29: Growth | J29: =IFERROR(VLOOKUP(J$7,Inputs!$E$19:$J$23,5,FALSE)/12+(VLOOKUP(MONTH(J$9),Modeling!$B$5:$L$16,11,FALSE)),(VLOOKUP(5,Inputs!$E$19:$J$23,5,FALSE)/12+(VLOOKUP(MONTH(J$9),Modeling!$B$5:$L$16,11,FALSE)))) -> 0.0033333333 | K29: =IFERROR(VLOOKUP(K$7,Inputs!$E$19:$J$23,5,FALSE)/12+(VLOOKUP(MONTH(K$9),Modeling!$B$5:$L$16,11,FALSE)),(VLOOKUP(5,Inputs!$E$19:$J$23,5,FALSE)/12+(VLOOKUP(MONTH(K$9),Modeling!$B$5:$L$16,11,FALSE)))) -> 0.0033333333 | L29: =IFERROR(VLOOKUP(L$7,Inputs!$E$19:$J$23,5,FALSE)/12+(VLOOKUP(MONTH(L$9),Modeling!$B$5:$L$16,11,FALSE)),(VLOOKUP(5,Inputs!$E$19:$J$23,5,FALSE)/12+(VLOOKUP(MONTH(L$9),Modeling!$B$5:$L$16,11,FALSE)))) -> 0.013333333 | M29: =IFERROR(VLOOKUP(M$7,Inputs!$E$19:$J$23,5,FALSE)/12+(VLOOKUP(MONTH(M$9),Modeling!$B$5:$L$16,11,FALSE)),(VLOOKUP(5,Inputs!$E$19:$J$23,5,FALSE)/12+(VLOOKUP(MONTH(M$9),Modeling!$B$5:$L$16,11,FALSE)))) -> 0.043333333 | N29: =IFERROR(VLOOKUP(N$7,Inputs!$E$19:$J$23,5,FALSE)/12+(VLOOKUP(MONTH(N$9),Modeling!$B$5:$L$16,11,FALSE)),(VLOOKUP(5,Inputs!$E$19:$J$23,5,FALSE)/12+(VLOOKUP(MONTH(N$9),Modeling!$B$5:$L$16,11,FALSE)))) -> 0.043333333 | O29: =IFERROR(VLOOKUP(O$7,Inputs!$E$19:$J$23,5,FALSE)/12+(VLOOKUP(MONTH(O$9),Modeling!$B$5:$L$16,11,FALSE)),(VLOOKUP(5,Inputs!$E$19:$J$23,5,FALSE)/12+(VLOOKUP(MONTH(O$9),Modeling!$B$5:$L$16,11,FALSE)))) -> 0.028333333 | P29: =IFERROR(VLOOKUP(P$7,Inputs!$E$19:$J$23,5,FALSE)/12+(VLOOKUP(MONTH(P$9),Modeling!$B$5:$L$16,11,FALSE)),(VLOOKUP(5,Inputs!$E$19:$J$23,5,FALSE)/12+(VLOOKUP(MONTH(P$9),Modeling!$B$5:$L$16,11,FALSE)))) -> 0.0033333333 | Q29: =IFERROR(VLOOKUP(Q$7,Inputs!$E$19:$J$23,5,FALSE)/12+(VLOOKUP(MONTH(Q$9),Modeling!$B$5:$L$16,11,FALSE)),(VLOOKUP(5,Inputs!$E$19:$J$23,5,FALSE)/12+(VLOOKUP(MONTH(Q$9),Modeling!$B$5:$L$16,11,FALSE)))) -> -0.056666667 | ... BU29: =IFERROR(VLOOKUP(BU$7,Inputs!$E$19:$J$23,5,FALSE)/12+(VLOOKUP(MONTH(BU$9),Modeling!$B$5:$L$16,11,FALSE)),(VLOOKUP(5,Inputs!$E$19:$J$23,5,FALSE)/12+(VLOOKUP(MONTH(BU$9),Modeling!$B$5:$L$16,11,FALSE)))) -> 0.043333333 | BW29: =SUMIF($J$6:$BU$6,BW$9,$J29:$BU29) -> 0.04 | BX29: =SUMIF($J$6:$BU$6,BX$9,$J29:$BU29) -> 0.04 | BY29: =SUMIF($J$6:$BU$6,BY$9,$J29:$BU29) -> 0.04 | BZ29: =SUMIF($J$6:$BU$6,BZ$9,$J29:$BU29) -> 0.04 | CA29: =SUMIF($J$6:$BU$6,CA$9,$J29:$BU29) -> 0.04 | CB29: =CA29 -> 0.04 | CC29: =CB29 -> 0.04 | CD29: =CC29 -> 0.04 | CE29: =CD29 -> 0.04 | CF29: =CE29 -> 0.04 | CG29: =CF29 -> 0.04 | CH29: =CG29 -> 0.04 | CI29: =CH29 -> 0.04 | ... CK29: =CJ29 -> 0.04
A30: =$F$2 -> 0 | B30: AvgNER | F30: Effective Rate | I30: =Inputs!$J$16*VLOOKUP(MONTH(EOMONTH(Inputs!$C$8,-1)),Modeling!$B$5:$M$16,12,FALSE) -> 17.789291 | J30: =I30*(1+J29) -> 17.848589 | K30: =J30*(1+K29) -> 17.908084 | L30: =K30*(1+L29) -> 18.146859 | M30: =L30*(1+M29) -> 18.933222 | N30: =M30*(1+N29) -> 19.753662 | O30: =N30*(1+O29) -> 20.313349 | P30: =O30*(1+P29) -> 20.38106 | Q30: =P30*(1+Q29) -> 19.226134 | ... BU30: =BT30*(1+BU29) -> 22.637424 | BW30: =AVERAGEIF($J$6:$BU$6,BW$9,$J30:$BU30) -> 18.918678 | BX30: =AVERAGEIF($J$6:$BU$6,BX$9,$J30:$BU30) -> 19.607006 | BY30: =AVERAGEIF($J$6:$BU$6,BY$9,$J30:$BU30) -> 20.320378 | BZ30: =AVERAGEIF($J$6:$BU$6,BZ$9,$J30:$BU30) -> 21.059704 | CA30: =AVERAGEIF($J$6:$BU$6,CA$9,$J30:$BU30) -> 21.82593 | CB30: =CA30*(1+Inputs!$C$34) -> 22.698967 | CC30: =CB30*(1+Inputs!$C$34) -> 23.606926 | CD30: =CC30*(1+Inputs!$C$34) -> 24.551203 | CE30: =CD30*(1+Inputs!$C$34) -> 25.533251 | CF30: =CE30*(1+Inputs!$C$34) -> 26.554581 | CG30: =CF30*(1+Inputs!$C$34) -> 27.616765 | CH30: =CG30*(1+Inputs!$C$34) -> 28.721435 | CI30: =CH30*(1+Inputs!$C$34) -> 29.870293 | ... CK30: =CJ30*(1+Inputs!$C$34) -> 32.307709
A32: =$F$2 -> 0 | B32: AvgFullPriceAsk | F32: Full Price Rental Rate | J32: =Monthly!D14 -> 19.335971 | K32: =Monthly!E14 -> 19.400425 | L32: =Monthly!F14 -> 19.659097 | M32: =Monthly!G14 -> 20.510991 | N32: =Monthly!H14 -> 21.399801 | O32: =Monthly!I14 -> 22.006128 | P32: =Monthly!J14 -> 22.079482 | Q32: =Monthly!K14 -> 20.828311 | ... BU32: =Monthly!BO14 -> 23.558871 | BW32: =AVERAGEIF($J$6:$BU$6,BW$9,$J32:$BU32) -> 20.495235 | BX32: =AVERAGEIF($J$6:$BU$6,BX$9,$J32:$BU32) -> 21.240923 | BY32: =AVERAGEIF($J$6:$BU$6,BY$9,$J32:$BU32) -> 21.716653 | BZ32: =AVERAGEIF($J$6:$BU$6,BZ$9,$J32:$BU32) -> 21.865785 | CA32: =AVERAGEIF($J$6:$BU$6,CA$9,$J32:$BU32) -> 22.661339 | CB32: =CA32*(1+Inputs!$C$34) -> 23.567792 | CC32: =CB32*(1+Inputs!$C$34) -> 24.510504 | CD32: =CC32*(1+Inputs!$C$34) -> 25.490924 | CE32: =CD32*(1+Inputs!$C$34) -> 26.510561 | CF32: =CE32*(1+Inputs!$C$34) -> 27.570984 | CG32: =CF32*(1+Inputs!$C$34) -> 28.673823 | CH32: =CG32*(1+Inputs!$C$34) -> 29.820776 | CI32: =CH32*(1+Inputs!$C$34) -> 31.013607 | ... CK32: =CJ32*(1+Inputs!$C$34) -> 33.544317
A33: =$F$2 -> 0 | B33: AvgRentRate | F33: Rental Rate | J33: =Monthly!D23 -> 18.175813 | K33: =Monthly!E23 -> 18.236399 | L33: =Monthly!F23 -> 18.479551 | M33: =Monthly!G23 -> 19.280332 | N33: =Monthly!H23 -> 20.115813 | O33: =Monthly!I23 -> 20.685761 | P33: =Monthly!J23 -> 20.754713 | Q33: =Monthly!K23 -> 19.578613 | ... BU33: =Monthly!BO23 -> 22.145338 | BW33: =AVERAGEIF($J$6:$BU$6,BW$9,$J33:$BU33) -> 19.265521 | BX33: =AVERAGEIF($J$6:$BU$6,BX$9,$J33:$BU33) -> 19.966468 | BY33: =AVERAGEIF($J$6:$BU$6,BY$9,$J33:$BU33) -> 20.413654 | BZ33: =AVERAGEIF($J$6:$BU$6,BZ$9,$J33:$BU33) -> 20.553838 | CA33: =AVERAGEIF($J$6:$BU$6,CA$9,$J33:$BU33) -> 21.301659 | CB33: =CA33*(1+Inputs!$C$34) -> 22.153725 | CC33: =CB33*(1+Inputs!$C$34) -> 23.039874 | CD33: =CC33*(1+Inputs!$C$34) -> 23.961469 | CE33: =CD33*(1+Inputs!$C$34) -> 24.919928 | CF33: =CE33*(1+Inputs!$C$34) -> 25.916725 | CG33: =CF33*(1+Inputs!$C$34) -> 26.953394 | CH33: =CG33*(1+Inputs!$C$34) -> 28.031529 | CI33: =CH33*(1+Inputs!$C$34) -> 29.152791 | ... CK33: =CJ33*(1+Inputs!$C$34) -> 31.531658
A34: =$F$2 -> 0 | B34: IPRPSF | F34: In-Place Rate | I34: =IFERROR((Inputs!$C$20-Inputs!$C$30)/(Inputs!$C$18-Inputs!$C$24)*12,0) -> 0 | J34: =(J54/J25)*12 -> 18.175813 | K34: =(K54/K25)*12 -> 18.205922 | L34: =(L54/L25)*12 -> 18.324384 | M34: =(M54/M25)*12 -> 18.644272 | N34: =(N54/N25)*12 -> 19.16545 | O34: =(O54/O25)*12 -> 19.760769 | P34: =(P54/P25)*12 -> 20.085302 | Q34: =(Q54/Q25)*12 -> 20.121592 | ... BU34: =(BU54/BU25)*12 -> 24.160574 | BW34: =BW54/BW25 -> 19.859233 | BX34: =BX54/BX25 -> 20.810242 | BY34: =BY54/BY25 -> 21.794342 | BZ34: =BZ54/BZ25 -> 22.648495 | CA34: =CA54/CA25 -> 23.666244 | CB34: =CB54/CB25 -> 24.612894 | CC34: =CC54/CC25 -> 25.59741 | CD34: =CD54/CD25 -> 26.621306 | ... CK34: =CK54/CK25 -> 35.031823
A35: =$F$2 -> 0 | D35: Discounts
A36: =$F$2 -> 0 | B36: Disc % | F36: Discounts (% of Rental Income) | J36: =IF(Inputs!$I$36=0,Monthly!D42,Inputs!$I$36) -> -0.025 | K36: =IF(Inputs!$I$36=0,Monthly!E42,Inputs!$I$36) -> -0.025 | L36: =IF(Inputs!$I$36=0,Monthly!F42,Inputs!$I$36) -> -0.025 | M36: =IF(Inputs!$I$36=0,Monthly!G42,Inputs!$I$36) -> -0.025 | N36: =IF(Inputs!$I$36=0,Monthly!H42,Inputs!$I$36) -> -0.025 | O36: =IF(Inputs!$I$36=0,Monthly!I42,Inputs!$I$36) -> -0.025 | P36: =IF(Inputs!$I$36=0,Monthly!J42,Inputs!$I$36) -> -0.025 | Q36: =IF(Inputs!$I$36=0,Monthly!K42,Inputs!$I$36) -> -0.025 | ... BU36: =IF(Inputs!$I$36=0,Monthly!BO42,Inputs!$I$36) -> -0.025 | BW36: =BW55/BW54 -> -0.025 | BX36: =BX55/BX54 -> -0.025 | BY36: =BY55/BY54 -> -0.025 | BZ36: =BZ55/BZ54 -> -0.025 | CA36: =CA55/CA54 -> -0.025 | CB36: =CB55/CB54 -> -0.025 | CC36: =CC55/CC54 -> -0.025 | CD36: =CD55/CD54 -> -0.025 | ... CK36: =CK55/CK54 -> -0.025
A38: =$F$2 -> 0
A39: =$F$2 -> 0 | D39: Rental Income Calculation | BW39: Rental Income Calc
A40: =$F$2 -> 0 | B40: Move-In Revenue (non-Prorated) | F40: Move-In $ | J40: =Monthly!D22 -> 3497.1153 | K40: =Monthly!E22 -> 3466.4432 | L40: =Monthly!F22 -> 5195.5217 | M40: =Monthly!G22 -> 5936.0469 | N40: =Monthly!H22 -> 9519.1296 | O40: =Monthly!I22 -> 9144.2548 | P40: =Monthly!J22 -> 9051.8399 | Q40: =Monthly!K22 -> 8135.1497 | ... BU40: =Monthly!BO22 -> 7822.7081 | BW40: =SUMIF($J$6:$BU$6,BW$9,$J40:$BU40) -> 83572.084 | BX40: =SUMIF($J$6:$BU$6,BX$9,$J40:$BU40) -> 142797.8 | BY40: =SUMIF($J$6:$BU$6,BY$9,$J40:$BU40) -> 160047.55 | BZ40: =SUMIF($J$6:$BU$6,BZ$9,$J40:$BU40) -> 117889.24 | CA40: =SUMIF($J$6:$BU$6,CA$9,$J40:$BU40) -> 114226.31 | CB40: =SUMIF($J$7:$BP$7,CB$7,$J40:$BP40) -> 0 | CC40: =SUMIF($J$7:$BP$7,CC$7,$J40:$BP40) -> 0 | CD40: =SUMIF($J$7:$BP$7,CD$7,$J40:$BP40) -> 0 | CE40: =SUMIF($J$7:$BP$7,CE$7,$J40:$BP40) -> 0 | CF40: =SUMIF($J$7:$BP$7,CF$7,$J40:$BP40) -> 0 | CG40: =SUMIF($J$7:$BP$7,CG$7,$J40:$BP40) -> 0 | CH40: =SUMIF($J$7:$BP$7,CH$7,$J40:$BP40) -> 0 | CI40: =SUMIF($J$7:$BP$7,CI$7,$J40:$BP40) -> 0 | ... CK40: =SUMIF($J$7:$BP$7,CK$7,$J40:$BP40) -> 0
A41: =$F$2 -> 0 | B41: Move-Out Revenue (non-Prorated) | F41: Move-Out $ | J41: =Monthly!D27 -> 0 | K41: =Monthly!E27 -> 0 | L41: =Monthly!F27 -> -349.25698 | M41: =Monthly!G27 -> -766.34323 | N41: =Monthly!H27 -> -1220.3535 | O41: =Monthly!I27 -> -2035.2426 | P41: =Monthly!J27 -> -2825.4602 | Q41: =Monthly!K27 -> -3931.7866 | ... BU41: =Monthly!BO27 -> -7312.0152 | BW41: =SUMIF($J$6:$BU$6,BW$9,$J41:$BU41) -> -27935.482 | BX41: =SUMIF($J$6:$BU$6,BX$9,$J41:$BU41) -> -83685.289 | BY41: =SUMIF($J$6:$BU$6,BY$9,$J41:$BU41) -> -123309.61 | BZ41: =SUMIF($J$6:$BU$6,BZ$9,$J41:$BU41) -> -129408.19 | CA41: =SUMIF($J$6:$BU$6,CA$9,$J41:$BU41) -> -123401.47 | CB41: =SUMIF($J$7:$BP$7,CB$7,$J41:$BP41) -> 0 | CC41: =SUMIF($J$7:$BP$7,CC$7,$J41:$BP41) -> 0 | CD41: =SUMIF($J$7:$BP$7,CD$7,$J41:$BP41) -> 0 | CE41: =SUMIF($J$7:$BP$7,CE$7,$J41:$BP41) -> 0 | CF41: =SUMIF($J$7:$BP$7,CF$7,$J41:$BP41) -> 0 | CG41: =SUMIF($J$7:$BP$7,CG$7,$J41:$BP41) -> 0 | CH41: =SUMIF($J$7:$BP$7,CH$7,$J41:$BP41) -> 0 | CI41: =SUMIF($J$7:$BP$7,CI$7,$J41:$BP41) -> 0 | ... CK41: =SUMIF($J$7:$BP$7,CK$7,$J41:$BP41) -> 0
A42: =$F$2 -> 0 | B42: Rate Increase Revenue (non-prorated) | F42: TRIs | I42: =Inputs!$I$25 -> 0.12 | J42: =Monthly!D31 -> 0 | K42: =Monthly!E31 -> 0 | L42: =Monthly!F31 -> 0 | M42: =Monthly!G31 -> 0 | N42: =Monthly!H31 -> 0 | O42: =Monthly!I31 -> 335.72307 | P42: =Monthly!J31 -> 228.86099 | Q42: =Monthly!K31 -> 343.17671 | ... BU42: =Monthly!BO31 -> 1279.9978 | BW42: =SUMIF($J$6:$BU$6,BW$9,$J42:$BU42) -> 3023.8625 | BX42: =SUMIF($J$6:$BU$6,BX$9,$J42:$BU42) -> 9393.2651 | BY42: =SUMIF($J$6:$BU$6,BY$9,$J42:$BU42) -> 15022.895 | BZ42: =SUMIF($J$6:$BU$6,BZ$9,$J42:$BU42) -> 17371.69 | CA42: =SUMIF($J$6:$BU$6,CA$9,$J42:$BU42) -> 17385.013 | CB42: =SUMIF($J$7:$BP$7,CB$7,$J42:$BP42) -> 0 | CC42: =SUMIF($J$7:$BP$7,CC$7,$J42:$BP42) -> 0 | CD42: =SUMIF($J$7:$BP$7,CD$7,$J42:$BP42) -> 0 | CE42: =SUMIF($J$7:$BP$7,CE$7,$J42:$BP42) -> 0 | CF42: =SUMIF($J$7:$BP$7,CF$7,$J42:$BP42) -> 0 | CG42: =SUMIF($J$7:$BP$7,CG$7,$J42:$BP42) -> 0 | CH42: =SUMIF($J$7:$BP$7,CH$7,$J42:$BP42) -> 0 | CI42: =SUMIF($J$7:$BP$7,CI$7,$J42:$BP42) -> 0 | ... CK42: =SUMIF($J$7:$BP$7,CK$7,$J42:$BP42) -> 0
A43: =$F$2 -> 0 | F43: Ending Storage Rental Income | I43: =Inputs!$C$20-Inputs!$C$30 -> 0 | J43: =I43+SUM(J40:J42) -> 3497.1153 | K43: =J43+SUM(K40:K42) -> 6963.5585 | L43: =K43+SUM(L40:L42) -> 11809.823 | M43: =L43+SUM(M40:M42) -> 16979.527 | N43: =M43+SUM(N40:N42) -> 25278.303 | O43: =N43+SUM(O40:O42) -> 32723.038 | P43: =O43+SUM(P40:P42) -> 39178.279 | Q43: =P43+SUM(Q40:Q42) -> 43724.819 | ... BU43: =BT43+SUM(BU40:BU42) -> 195064.31 | BW43: =SUMIF($J$7:$BP$7,BW$9,$J43:$BP43) -> 393810.09 | BX43: =SUMIF($J$7:$BP$7,BX$9,$J43:$BP43) -> 1164295.8 | BY43: =SUMIF($J$7:$BP$7,BY$9,$J43:$BP43) -> 1882391.1 | BZ43: =SUMIF($J$7:$BP$7,BZ$9,$J43:$BP43) -> 2204659.7 | CA43: =SUMIF($J$7:$BP$7,CA$9,$J43:$BP43) -> 2110740.3 | CB43: =SUMIF($J$7:$BP$7,CB$7,$J43:$BP43) -> 0 | CC43: =SUMIF($J$7:$BP$7,CC$7,$J43:$BP43) -> 0 | CD43: =SUMIF($J$7:$BP$7,CD$7,$J43:$BP43) -> 0 | CE43: =SUMIF($J$7:$BP$7,CE$7,$J43:$BP43) -> 0 | CF43: =SUMIF($J$7:$BP$7,CF$7,$J43:$BP43) -> 0 | CG43: =SUMIF($J$7:$BP$7,CG$7,$J43:$BP43) -> 0 | CH43: =SUMIF($J$7:$BP$7,CH$7,$J43:$BP43) -> 0 | CI43: =SUMIF($J$7:$BP$7,CI$7,$J43:$BP43) -> 0 | ... CK43: =SUMIF($J$7:$BP$7,CK$7,$J43:$BP43) -> 0
